Workbook

Sheet Final Scoring
D1: 2019 COMMISSIONER'S OFFICE SUSTAINABILITY CHALLENGE
A2: Participant:
A3: Sustainability Team Member:
A4: # | B4: Enviro. Benefit | C4: Action Type | D4: Category | E4: Subcategory | F4: Behavior/Action | G4: Points Available | H4: Point Scoring | I4: Points Earned | J4: Sustainability Tip
A5: 1 | B5: Kick-Off | C5: In Person | D5: Footprint | E5: - | F5: Complete the Ecological Footprint Calculator | G5: 15 | H5: Leader with the smallest footprint earns the most points (smallest = 15 pts, 2nd smallest = 14 pts, 3rd smallest = 13 pts, etc.) | J5: A person’s ecological footprint includes both personal and societal impacts – individual lifestyle choices (food, mobility, etc.) are important to reducing our environmental impacts; however, systems and infrastructure changes are also needed. As a state environmental agency, the MPCA has the ability and responsibility to influence both. https://www.footprintcalculator.org/
A6: 2 | B6: Kick-Off | C6: In Person | D6: Footprint | E6: - | F6: Complete the Water Footprint Calculator | G6: 15 | H6: Leader with the smallest footprint earns the most points (smallest = 15 pts, 2nd smallest = 14 pts, 3rd smallest = 13 pts, etc.) | J6: Water footprints are an assessment of direct and virtual water use patterns. Fresh water is vital to life, but as the world’s population grows, so does its use of water. It takes water – a lot of it – to produce food, to make energy and to manufacture consumer products. This is what’s known as virtual water. https://www.watercalculator.org/
A7: 3 | B7: Kick-Off | C7: In Person | D7: Waste Sort | E7: - | F7: Complete a waste sort, determining which items should be recycled, composted, or trashed | G7: 8 | H7: 8 pts = 100% accuracy 5 pts = 75% accuracy 2 pts = 50% accuracy 0pts = 50% accuracy | J7: Preventing waste is the best option, but when you have items needing disposal, State statute includes a waste hierarchy indicating which methods have the least environmental impact. Between these three options, it’s better to recycle when possible, then compost, and then finally landfill (trash).
A8: 4 | B8: Best Option | C8: Action Throughout the Week | D8: 01 - Food | E8: Meatless | F8: Reduce environmental impact of food choices with less meat, namely red meat. | G8: =7*'Daily Scoring - Day 1'!H5 -> 56 | H8: Sum of Daily Points | I8: =SUM('Daily Scoring - Day 1'!K5,'Daily Scoring - Day 2'!K5,'Daily Scoring - Day 3'!K5,'Daily Scoring - Day 4'!K5,'Daily Scoring - Day 5'!K5,'Daily Scoring - Day 6'!K5,'Daily Scoring - Day 7'!K5) -> 0
A9: 5 | B9: Good Option | C9: Action Throughout the Week | D9: 01 - Food | E9: Wasted Food | F9: Reduce environmental impact of food system with less wasted food. | G9: =7*'Daily Scoring - Day 1'!H6 -> 42 | H9: Sum of Daily Points | I9: =SUM('Daily Scoring - Day 1'!K6,'Daily Scoring - Day 2'!K6,'Daily Scoring - Day 3'!K6,'Daily Scoring - Day 4'!K6,'Daily Scoring - Day 5'!K6,'Daily Scoring - Day 6'!K6,'Daily Scoring - Day 7'!K6) -> 0
A10: 6 | B10: Helpful Option | C10: Action Throughout the Week | D10: 01 - Food | E10: Food and Drink | F10: Avoid single-use materials and use reusable drink containers. | G10: =7*'Daily Scoring - Day 1'!H7 -> 28 | H10: Sum of Daily Points | I10: =SUM('Daily Scoring - Day 1'!K7,'Daily Scoring - Day 2'!K7,'Daily Scoring - Day 3'!K7,'Daily Scoring - Day 4'!K7,'Daily Scoring - Day 5'!K7,'Daily Scoring - Day 6'!K7,'Daily Scoring - Day 7'!K7) -> 0
A11: 7 | B11: Helpful Option | C11: Action Throughout the Week | D11: 01 - Food | E11: Food and Drink | F11: Avoid single-use materials with less take-out, delivery, and/or fast food. | G11: =7*'Daily Scoring - Day 1'!H8 -> 28 | H11: Sum of Daily Points | I11: =SUM('Daily Scoring - Day 1'!K8,'Daily Scoring - Day 2'!K8,'Daily Scoring - Day 3'!K8,'Daily Scoring - Day 4'!K8,'Daily Scoring - Day 5'!K8,'Daily Scoring - Day 6'!K8,'Daily Scoring - Day 7'!K8) -> 0
A12: 8 | B12: Best Option | C12: Action Throughout the Week | D12: 02 - Shelter & Energy | E12: Unplug Electronics | F12: Reduce energy use by unplugging electronics. | G12: =7*'Daily Scoring - Day 1'!H9 -> 56 | H12: Sum of Daily Points | I12: =SUM('Daily Scoring - Day 1'!K9,'Daily Scoring - Day 2'!K9,'Daily Scoring - Day 3'!K9,'Daily Scoring - Day 4'!K9,'Daily Scoring - Day 5'!K9,'Daily Scoring - Day 6'!K9,'Daily Scoring - Day 7'!K9) -> 0
A13: 9 | B13: Good Option | C13: Action Throughout the Week | D13: 02 - Shelter & Energy | E13: Shut Off Computer | F13: Reduce energy use by turning off computer/monitor. | G13: =7*'Daily Scoring - Day 1'!H10 -> 42 | H13: Sum of Daily Points | I13: =SUM('Daily Scoring - Day 1'!K10,'Daily Scoring - Day 2'!K10,'Daily Scoring - Day 3'!K10,'Daily Scoring - Day 4'!K10,'Daily Scoring - Day 5'!K10,'Daily Scoring - Day 6'!K10,'Daily Scoring - Day 7'!K10) -> 0
A14: 10 | B14: Helpful Option | C14: Action Throughout the Week | D14: 02 - Shelter & Energy | E14: Blinds | F14: Reduce energy use by closing the blinds. | G14: =7*'Daily Scoring - Day 1'!H11 -> 28 | H14: Sum of Daily Points | I14: =SUM('Daily Scoring - Day 1'!K11,'Daily Scoring - Day 2'!K11,'Daily Scoring - Day 3'!K11,'Daily Scoring - Day 4'!K11,'Daily Scoring - Day 5'!K11,'Daily Scoring - Day 6'!K11,'Daily Scoring - Day 7'!K11) -> 0
A15: 11 | B15: Best Option | C15: Action Throughout the Week | D15: 03 - Mobility | E15: General Travel | F15: Reduce environmental impact with more sustainable modes of transportation. | G15: =7*'Daily Scoring - Day 1'!H12 -> 56 | H15: Sum of Daily Points | I15: =SUM('Daily Scoring - Day 1'!K12,'Daily Scoring - Day 2'!K12,'Daily Scoring - Day 3'!K12,'Daily Scoring - Day 4'!K12,'Daily Scoring - Day 5'!K12,'Daily Scoring - Day 6'!K12,'Daily Scoring - Day 7'!K12) -> 0
A16: 12 | B16: Helpful Option | C16: Action Throughout the Week | D16: 03 - Mobility | E16: Planning | F16: Reduce environmental impact with more intentional travel plans. | G16: =7*'Daily Scoring - Day 1'!H13 -> 28 | H16: Sum of Daily Points | I16: =SUM('Daily Scoring - Day 1'!K13,'Daily Scoring - Day 2'!K13,'Daily Scoring - Day 3'!K13,'Daily Scoring - Day 4'!K13,'Daily Scoring - Day 5'!K13,'Daily Scoring - Day 6'!K13,'Daily Scoring - Day 7'!K13) -> 0
A17: 13 | B17: Good Option | C17: Action Throughout the Week | D17: 03 - Mobility | E17: Work Travel | F17: Reduce environmental impact with more sustainable modes of transportation. | G17: =7*'Daily Scoring - Day 1'!H14 -> 42 | H17: Sum of Daily Points | I17: =SUM('Daily Scoring - Day 1'!K14,'Daily Scoring - Day 2'!K14,'Daily Scoring - Day 3'!K14,'Daily Scoring - Day 4'!K14,'Daily Scoring - Day 5'!K14,'Daily Scoring - Day 6'!K14,'Daily Scoring - Day 7'!K14) -> 0
A18: 14 | B18: Helpful Option | C18: Action Throughout the Week | D18: 03 - Mobility | E18: Stairs | F18: Reduce energy use and improve health by taking the stairs. | G18: =7*'Daily Scoring - Day 1'!H15 -> 28 | H18: Sum of Daily Points | I18: =SUM('Daily Scoring - Day 1'!K15,'Daily Scoring - Day 2'!K15,'Daily Scoring - Day 3'!K15,'Daily Scoring - Day 4'!K15,'Daily Scoring - Day 5'!K15,'Daily Scoring - Day 6'!K15,'Daily Scoring - Day 7'!K15) -> 0
A19: 15 | B19: Best Option | C19: Action Throughout the Week | D19: 04 - Goods/Services | E19: Single-Use Plastic | F19: Avoid single-use materials and use reusable options. | G19: =7*'Daily Scoring - Day 1'!H16 -> 56 | H19: Sum of Daily Points | I19: =SUM('Daily Scoring - Day 1'!K16,'Daily Scoring - Day 2'!K16,'Daily Scoring - Day 3'!K16,'Daily Scoring - Day 4'!K16,'Daily Scoring - Day 5'!K16,'Daily Scoring - Day 6'!K16,'Daily Scoring - Day 7'!K16) -> 0
... A28: 24 | B28: Good Option | C28: Action Throughout the Week | D28: 05 - Water | E28: Water Quality | F28: Protect water quality through intentional management of icy sidewalks. | G28: =7*'Daily Scoring - Day 1'!H25 -> 42 | H28: Sum of Daily Points | I28: =SUM('Daily Scoring - Day 1'!K25,'Daily Scoring - Day 2'!K25,'Daily Scoring - Day 3'!K25,'Daily Scoring - Day 4'!K25,'Daily Scoring - Day 5'!K25,'Daily Scoring - Day 6'!K25,'Daily Scoring - Day 7'!K25) -> 0
A29: 25 | B29: Extra Credit | C29: General Action | D29: 01 - Food | E29: Compost | F29: Do you compost at home (backyard, organics collection, drop-off)? | G29: 2 | H29: Extra Credit - yes / no | J29: Learn more about composting your backyard: https://www.pca.state.mn.us/waste/composting-your-backyard Learn what can go in your organics bin: http://www.minneapolismn.gov/solid-waste/organics/acceptable-organics Check out where organics drop-offs are located: http://www.mncompostingcouncil.org/organics-collection--drop-off-programs.html
A30: 26 | B30: Extra Credit | C30: General Action | D30: 02 - Shelter & Energy | E30: Conference Rooms | F30: Did you make sure that computers, projectors, and lights were shut off in meetings rooms at the end of a meeting to conserve energy during the challenge? | G30: 2 | H30: Extra Credit - yes / no | J30: https://lorax.pca.state.mn.us/green-meetings
A31: 27 | B31: Extra Credit | C31: General Action | D31: 03 - Mobility | E31: Zero Emissions | F31: Did you use zero emissions transportation modes every day of the challenge (i.e. walk to a meeting outside of the PCA, use an electric vehicle, video conference instead of travel)? | G31: 2 | H31: Extra Credit - yes / no | J31: You are a sustainability rockstar!
A32: 28 | B32: Extra Credit | C32: General Action | D32: 03 - Mobility | E32: Carbon Offsets | F32: Have you purchased carbon offsets for any flights taken in the last year? | G32: 2 | H32: Extra Credit - yes / no | J32: https://www.nytimes.com/2019/07/24/climate/nyt-climate-newsletter-carbon-offsets.html
A33: 29 | B33: Extra Credit | C33: General Action | D33: 04 - Goods/Services | E33: Secondhand Clothing | F33: Have you purchased secondhand clothing instead of new clothes when shopping in the last 3 months? | G33: 2 | H33: Extra Credit - yes / no | J33: Fashion is considered one of the most polluting industries in the world, and recognized for unsafe and exploitative working conditions. Avoid fast fashion! Buy fewer, and more durable clothes and shop at secondhand retailers. Remember - donating clothing is a good alternative to throwing away directly, but don't view that as an opportunity to then go on a new shopping spree! https://www.wri.org/blog/2017/07/apparel-industrys-environmental-impact-6-graphics If you haven't yet, participate in the MPCA clothing swaps or host one in your community! https://www.wri.org/blog/2017/07/apparel-industrys-environmental-impact-6-graphics
A34: 30 | B34: Extra Credit | C34: General Action | D34: 05 - Water | E34: Washing Clothes | F34: Do you wear your clothes multiple times before washing them? | G34: 2 | H34: Extra Credit - yes / no | J34: If you're worried about dressing ethically, you should think about how often you wash/dry your clothes as it is one of the greatest impacts of your clothing in its life cycle. https://www.1millionwomen.com.au/blog/dirt-clothes-why-washing-less-more-sustainable/
A35: 31 | B35: Extra Credit | C35: General Action | D35: 04 - Goods/Services | E35: Materials | F35: When you have to buy something new, do you look for items that are light-weighted for materials or use recycled content to encourage circularity? | G35: 2 | H35: Extra Credit - yes / no | J35: Don't just buy something that can be recycled - buy something that is made from recycled content to help support markets. https://www.pca.state.mn.us/featured/reduce-reuse-and-buy-items-made-recycled-materials
A36: 32 | B36: Extra Credit | C36: General Action | D36: 04 - Goods/Services | E36: Electronic Statements | F36: Do you only get online/electronic bank statements and bills? | G36: 2 | H36: Extra Credit - yes / no | J36: Let's be real, it's much easier to manage when everything's online anyways. Still getting a lot of other junk mail? There are options to help you remove your name off some lists: https://www.pca.state.mn.us/too-much-junk-mail
A37: 33 | B37: Extra Credit | C37: General Action | D37: 02 - Shelter & Energy | E37: Alternative Energy | F37: Does your home have solar panels, do you purchase community solar shares, or are you enrolled in WindSource? | G37: 2 | H37: Extra Credit - yes / no | J37: https://mn.gov/commerce/consumers/your-home/energy-info/solar/ https://www.cleanenergyresourceteams.org/solargardens https://www.xcelenergy.com/programs_and_rebates/residential_programs_and_rebates/renewable_energy_options_residential/windsource_for_residences
A38: 34 | B38: Extra Credit | C38: General Action | D38: 02 - Shelter & Energy | E38: Home Performance | F38: Have you assessed your house and/or taken actions to improve your home's energy efficiency and performance? | G38: 2 | H38: Extra Credit - yes / no | J38: https://mn.gov/commerce/consumers/your-home/energy-info/efficiency/
A39: 35 | B39: Wrap-Up | C39: In Person | D39: Footprint | E39: - | F39: Complete the Ecological Footprint Calculator | G39: 15 | H39: Leader with the smallest footprint earns the most points (smallest = 15 pts, 2nd smallest = 14 pts, 3rd smallest = 13 pts, etc.) | J39: Leader with the most improvement will be recognized.
A40: 36 | B40: Wrap-Up | C40: In Person | D40: Footprint | E40: - | F40: Complete the Water Footprint Calculator | G40: 15 | H40: Leader with the smallest footprint earns the most points (smallest = 15 pts, 2nd smallest = 14 pts, 3rd smallest = 13 pts, etc.) | J40: Leader with the most improvement will be recognized.
F41: Total Points Available: | G41: =SUM(G5:G40) -> 942 | H41: Total Points Earned: | I41: =SUM(I5:I40) -> 0

Sheet Daily Scoring - Day 1
D1: DAILY SCORING - DAY 1
A2: Participant: | C2: ='Final Scoring'!C2 -> 0
A3: Sustainability Team Member: | C3: ='Final Scoring'!C3 -> 0
A4: # | B4: Environmental Benefit | C4: In person task? Action throughout the week? | D4: Category | E4: Subcategory | F4: Behavior/Action | G4: Points Available | H4: Weighted Available Points | I4: Point Scoring | J4: Points Earned | K4: Point Total (weighted by "Best," "Good," or "Helpful" action) | L4: Sustainability Tip
A5: 1 | B5: Best Option | C5: Action Throughout the Week | D5: 01 - Food | E5: Meatless | F5: Did you eat meat (red meat, white meat, fish/seafood) today? Did you eat primarily: - Red meat (beef, pork, lamb, etc.) - White meat (chicken) - Fish/seafood Was it locally sourced and organic? - Yes - No - Unsure | G5: 4 | H5: =G5*2 -> 8 | I5: No meat = 4 pts OR Red meat = 0 pts OR White meant OR Fish/seafood = 1 pt AND Local/Organic = +1 pt No OR Unsure = 0 pts | K5: =J5*2 -> 0 | L5: Already a vegetarian? Reduce your impact further by reducing the amount of animal products you consume (cheese, eggs, etc.), and choose organic, local options. It’s better for your health and great support for the MN economy! https://www.nytimes.com/interactive/2019/04/30/dining/climate-change-food-eating-habits.html
A6: 2 | B6: Good Option | C6: Action Throughout the Week | D6: 01 - Food | E6: Wasted Food | F6: Did you have food remaining that you didn’t save to eat later at any meals today? How many meals had wasted food? - Breakfast - Lunch - Dinner - Snacks only Did you compost or trash the wasted food? - Composted - Threw it in the trash | G6: 4 | H6: =G6*1.5 -> 6 | I6: No remaining food = 4 pts OR Every meal with composted wasted food = -.5 pts (from available 4 pts) OR Every meal with trashed wasted food = -1 pt (from available 4 pts) | K6: =J6*1.5 -> 0 | L6: The average American wastes 290lbs of food/year – composting is a great option for food scraps, but isn’t a solution to wasted food. Most of the greenhouse gas emissions in the life cycle of our food is from food production, not end-of-life management. Be conscious of how you store food, the size of portions you take, and how you save left-overs to reduce wasted food. https://www.pca.state.mn.us/simple-ways-cut-food-waste
A7: 3 | B7: Helpful Option | C7: Action Throughout the Week | D7: 01 - Food | E7: Food and Drink | F7: Were the majority of your beverages (coffee, water, soda, etc.) today served in: - a reusable container - a single-use container (compostable, recyclable, styrofoam, etc.) | G7: 4 | H7: =G7 -> 4 | I7: Reusable = 4 pts OR Single-use (compostable, non-compostable, styrofoam) cup = 0 pts | K7: =J7 -> 0 | L7: It is estimated that around 4 billion Starbucks disposable cups are thrown away annually in the US alone. Many coffee shops offer a discount for bringing your own mug. It is easy to bring your own mug to meetings and other events to avoid using disposable options when reusable mugs aren't made available. Learn More: More than Cups: Considering Sustainability in the Coffee Shop Industry - Daily Coffee News
A8: 4 | B8: Helpful Option | C8: Action Throughout the Week | D8: 01 - Food | E8: Food and Drink | F8: Did you order food today as take-out, delivery, or fast food? | G8: 4 | H8: =G8 -> 4 | I8: No ordered food = 4 pts OR Ordered food (delivered, take-out, fast food) = 0 pts | K8: =J8 -> 0 | L8: Did you know you can bring your own Tupperware to take leftovers home when you can’t finish your meal out? Keep one in your car and/or bag so you don't need to create demand for the single-use options.
A9: 5 | B9: Best Option | C9: Action Throughout the Week | D9: 02 - Shelter & Energy | E9: Unplug Electronics | F9: Did you unplug the electronics and appliances you own that draw the most power (i.e. computer and phone chargers, coffee maker, desktop, etc.) today? | G9: 4 | H9: =G9*2 -> 8 | I9: Unplugged electronics = 4 pts OR Didn't unplug electronics = 0 pts | K9: =J9*2 -> 0 | L9: Back in the day there was a difference between on and off. Now, it’s more complicated and roughly 50 devices and appliances in the typical American household are always drawing power, even when they appear to be off. Turn off power strips, and unplug when not in use! https://cleantechnica.com/2015/02/18/room-room-guide-ousting-energy-vampires-lurking-home/
A10: 6 | B10: Good Option | C10: Action Throughout the Week | D10: 02 - Shelter & Energy | E10: Shut Off Computer | F10: Did you shut off your computer/monitor at the end of the day? - Yes - No - Unsure Did you put your computer to sleep (lock, turn off monitors) when you were away throughout today? - Yes - No - Some of the time | G10: 4 | H10: =G10*1.5 -> 6 | I10: Shut off computer/monitor = 2 pts OR Unsure OR Didn't shut off computer/monitor = 0 pts AND Put computer to sleep when away = 2 pts OR Put computer to sleep some of the time = 1 pt OR Didn't put computer to sleep = 0 pts | K10: =J10*1.5 -> 0
A11: 7 | B11: Helpful Option | C11: Action Throughout the Week | D11: 02 - Shelter & Energy | E11: Blinds | F11: Did you shut your blinds during the day (summer) / at night (winter)? | G11: 4 | H11: =G11 -> 4 | I11: Blinds shut = 4 pts OR Blinds not shut = 0 pts | K11: =J11 -> 0 | L11: We all love natural light, especially if it allows to turn off indoor lighting, but when the sun is at its peak it's best to shut the blinds to keep the temperature down. Similarly in the winter, closing the blinds at night helps keeping the heat inside and unnecessarily cooling through exposed windows. Typical households and workplaces abuse thermostats, keeping it unnecessarily cool in the summer and overheated in the winter. Dress for the season to minimize your use!
A12: 8 | B12: Best Option | C12: Action Throughout the Week | D12: 03 - Mobility | E12: General Travel | F12: Did you use a personal vehicle today? What type of personal vehicle was used? - Gas-powered vehicle - Hybrid vehicle - Plug-in hybrid vehicle - All electric vehicle Did you carpool? | G12: 4 | H12: =G12*2 -> 8 | I12: No personal vehicle = 4 pts OR All electric vehicle = 3 pts OR Hybrid OR Plug-in hybrid vehicle = 2 pts Gas-powered vehicle = 0 pts AND Carpool = +1 pt No carpool = 0 pts | K12: =J12*2 -> 0 | L12: Nearly half of all air pollution in our state comes from vehicles. So one of the greatest contributions we can all make to improving air quality is to use alternatives to driving a car, especially as a sole occupant. Plus, did you know the MPCA is named a Bicycle Friendly Business? https://www.pca.state.mn.us/bus-bike-and-walk
A13: 9 | B13: Helpful Option | C13: Action Throughout the Week | D13: 03 - Mobility | E13: Planning | F13: Did you start your day today by planning your route and activities to minimize unnecessary or extra travel? - Yes - Yes - I made a plan but I had to deviate from the plan today - No | G13: 4 | H13: =G13 -> 4 | I13: Yes, planned = 4 pts OR Yes, but deviated = 2 pts OR No plan = 0 pts | K13: =J13 -> 0
A14: 10 | B14: Good Option | C14: Action Throughout the Week | D14: 03 - Mobility | E14: Work Travel | F14: Did you have to travel for work today? Did you use an alternative, more sustainable form of transportation for your work travel? - All electric vehicle - Public transportation - Bike/scooter/walk - Carpool | G14: 4 | H14: =G14*1.5 -> 6 | I14: No work travel OR Bike/scooter/walk = 4 pts OR Public transportation = 3 pts OR All electric vehicle OR Carpool = 2pts OR Travel without sustainable transport = 0 pts | K14: =J14*1.5 -> 0 | L14: If you're unsure how to navigate alternative transportation, never fear! The MPCA Sustainable Transit Team can provide tips, advice, and input on your best options. https://lorax.pca.state.mn.us/sustainable-transit-team
A15: 11 | B15: Helpful Option | C15: Action Throughout the Week | D15: 03 - Mobility | E15: Stairs | F15: Did you use the stairs instead of taking the elevator throughout the day today? - Yes - all the time - Yes - some of the time - No - always used the elevator | G15: 4 | H15: =G15 -> 4 | I15: All the time = 4 pts OR Some of the time = 2 pts OR Always used elevator = 0 pts | K15: =J15 -> 0 | L15: Taking the stairs has an environmental benefit because it lessens the energy consumption of our building, but it also offers important health benefits by lowering bad cholesterol levels, relieving stress, increase muscle strength, and improving joint health. http://www.startribune.com/want-a-cheap-way-to-get-healthier-and-develop-a-fabulous-butt-take-the-stairs/506050542/
A16: 12 | B16: Best Option | C16: Action Throughout the Week | D16: 04 - Goods/Services | E16: Single-Use Plastic | F16: Did you use single-use food and beverage items (including bottles/cans, containers, service ware, and utensils) today? | G16: 4 | H16: =G16*2 -> 8 | I16: Used single-use items = 0 pts OR Didn't use single-use items = 4 pts | K16: =J16*2 -> 0 | L16: Recyclable and compostable plastics are still single-use and have an environmental footprint – avoid use of these options by bringing your own plates/utensils/napkins to the MPCA cafeteria. https://lorax.pca.state.mn.us/news/reduce-waste-and-take-your-own-dishes-cafeteria
A17: 13 | B17: Best Option | C17: Action Throughout the Week | D17: 04 - Goods/Services | E17: Sustainable Cleaning | F17: Did you use non-toxic cleaning solutions and a reusable cleaning cloth/device (instead of paper towels, chemicals, etc.) when you cleaned today? | G17: 4 | H17: =G17*2 -> 8 | I17: Sustainable cleaning = 4 pts OR No sustainable cleaning = 0 pts | K17: =J17*2 -> 0 | L17: If you didn't clean every day, you may want to change some personal habits - kidding! MPCA have invested a lot of effort reaching out to community groups about the dangers of harsh, chemical-heavy cleaners. The best part is you can make them yourself and reduce the number of different cleaners needed for all of your household surfaces. Check out the Hennepin County video on FB for a tutorial: https://www.facebook.com/hennepin/videos/vb.211281525566478/2448986885120718/?type=2&theater
A18: 14 | B18: Good Option | C18: Action Throughout the Week | D18: 04 - Goods/Services | E18: Online Shopping | F18: Did you buy anything online today? | G18: 4 | H18: =G18*1.5 -> 6 | I18: Shopped online = 0 pts OR No online shopping = 4 pts | K18: =J18*1.5 -> 0
A19: 15 | B19: Good Option | C19: Action Throughout the Week | D19: 04 - Goods/Services | E19: Reusable Bags | F19: Did you shop for consumer goods (groceries, clothes, etc.) today? What bags did you use? - No bags - Reusable bags - Plastic/paper bags from the retailer | G19: 4 | H19: =G19*1.5 -> 6 | I19: No shopping = 4 pts OR No bags OR Reusable bags = 4 pts OR Plastic/paper bags = 0 pts | K19: =J19*1.5 -> 0 | L19: Have you checked out the bag tree set up by the lower-level exit to the parking lot? If you forget a bag and need to borrow one, take it and bring it back the next day. The Sustainability Team will clean and repair any that need fixing. https://lorax.pca.state.mn.us/news/tote-ally-sustainable-bag-share-station
A20: 16 | B20: Helpful Option | C20: Action Throughout the Week | D20: 04 - Goods/Services | E20: Paper Towels | F20: When drying your hands in the restroom today, did you: - Use multiple single-use paper towels - Use single-use paper towels, but ONLY one each time - Use a reusable cloth towel - Ues an electric hand dryer - Air dry/Shake it off | G20: 4 | H20: =G20 -> 4 | I20: Multiple single-use = 0 pts OR One single-use = 1 pt OR Electric hand dryer = 2 pts OR Reusable cloth towel = 3 pts OR Air dry/Shake it off = 4 pts | K20: =J20 -> 0 | L20: At home, use reusable cloths and/or rags. At work you can air-dry, or if you need help getting down to just one paper towel to start, check out this TED talk for instructions. https://www.ted.com/talks/joe_smith_how_to_use_a_paper_towel?language=en
A21: 17 | B21: Helpful Option | C21: Action Throughout the Week | D21: 04 - Goods/Services | E21: Printing | F21: Did you email documents, share or present a computer screen, and/or share via Skype/WebEex to avoid printing today? - Yes - all of the time - Yes - some of the time - No - always provided printed versions | G21: 4 | H21: =G21 -> 4 | I21: All the time = 4 pts OR Some of the time = 2 pts OR Always provided printed = 0 pts | K21: =J21 -> 0 | L21: Emailing agendas and meeting notes is just as helpful, if not more, than using paper with printed versions. Speaking of more sustainable meetings - are you using the green meeting checklist every time you plan or attend a meeting? https://lorax.pca.state.mn.us/green-meetings
A22: 18 | B22: Good Option | C22: Action Throughout the Week | D22: 05 - Water | E22: Washing Dishes | F22: When washing dishes today, did you primarily wash using: - A dishwasher - Pre-rinse and then a dishwasher - Hand washing in hot water - Hand washing in cold water | G22: 4 | H22: =G22*1.5 -> 6 | I22: Dishwasher = 4 pts OR Pre-rinse and dishwasher = 0 pts OR Hand wash in hot = 1 pts OR Hand wash in cold = 2 pts | K22: =J22*1.5 -> 0 | L22: Studies show that washing a load of dishes by hand can use up to 27 gallons of water and 2.5 kWh of energy to heat the water versus just 4 gallons of water and 1 kWH of energy when using an energy-efficient dishwasher (with a full load!) Learn More: Which is Better for the Enviornment: Washing Dishes By Hand Or The Dishwasher? - Huffpost
A23: 19 | B23: Best Option | C23: Action Throughout the Week | D23: 05 - Water | E23: Bathing | F23: Did you bathe today? - Yes - shower - Yes - bath - No (we aren't judging!) Did you shower for five minutes or less? Did you turn off the water while lathering and shaving? | G23: 4 | H23: =G23*2 -> 8 | I23: No Bathing = 4 pts OR Bath = 1 pt OR Shower = 2 pts AND Less than five min = +.5 pt OR Water off while lathering/shaving = +.5 pt | K23: =J23*2 -> 0
A24: 20 | B24: Helpful Option | C24: Action Throughout the Week | D24: 05 - Water | E24: Brushing Teeth | F24: Did you turn off the water while you brushed your teeth? | G24: 4 | H24: =G24 -> 4 | I24: Water off = 4 pts OR Water on = 0 pts | K24: =J24 -> 0
A25: 21 | B25: Good Option | C25: Action Throughout the Week | D25: 05 - Water | E25: Water Quality | F25: Did you maintain icy sidewalks or driveways today? What management style did you use primarily? - Plow, shovel, scrape - Reusable abrasives for traction (e.g. sand) - Deicers - Deicers, adhering to rules for the correct amount, distribution, and temperature | G25: 4 | H25: =G25*1.5 -> 6 | I25: No maintenance OR Plow, shovel, scrape = 4 pts OR Reusable abrasives = 3 pts OR Deicers, adhering to rules = 2 pts OR Deicers = 0 pts | K25: =J25*1.5 -> 0 | L25: Smart salting is important for local water quality. Use the Smart Salting Assessment tool to determine best practices and reduce salt use. Learn More: Smart Salting Assessment tool - MPCA
G26: =SUM(G5:G25) -> 84 | H26: =SUM(H5:H25) -> 122 | J26: =SUM(J5:J25) -> 0 | K26: =SUM(K5:K25) -> 0
G27: Available (unweighted) | H27: Available (weighted) | J27: Earned Total (unweighted) | K27: Earned Total (weighted)

Sheet Daily Scoring - Day 2
D1: DAILY SCORING - DAY 2
A2: Participant: | C2: ='Final Scoring'!C2 -> 0
A3: Sustainability Team Member: | C3: ='Final Scoring'!C3 -> 0
A4: # | B4: Environmental Benefit | C4: In person task? Action throughout the week? | D4: Category | E4: Subcategory | F4: Behavior/Action | G4: Points Available | H4: Weighted Available Points | I4: Point Scoring | J4: Points Earned | K4: Point Total (weighted by "Best," "Good," or "Helpful" action) | L4: Sustainability Tip
A5: 1 | B5: Best Option | C5: Action Throughout the Week | D5: 01 - Food | E5: Meatless | F5: Did you eat meat (red meat, white meat, fish/seafood) today? Did you eat primarily: - Red meat (beef, pork, lamb, etc.) - White meat (chicken) - Fish/seafood Was it locally sourced and organic? - Yes - No - Unsure | G5: 4 | H5: =G5*2 -> 8 | I5: No meat = 4 pts OR Red meat = 0 pts OR White meant OR Fish/seafood = 1 pt AND Local/Organic = +1 pt No OR Unsure = 0 pts | K5: =J5*2 -> 0 | L5: Already a vegetarian? Reduce your impact further by reducing the amount of animal products you consume (cheese, eggs, etc.), and choose organic, local options. It’s better for your health and great support for the MN economy! https://www.nytimes.com/interactive/2019/04/30/dining/climate-change-food-eating-habits.html
A6: 2 | B6: Good Option | C6: Action Throughout the Week | D6: 01 - Food | E6: Wasted Food | F6: Did you have food remaining that you didn’t save to eat later at any meals today? How many meals had wasted food? - Breakfast - Lunch - Dinner - Snacks only Did you compost or trash the wasted food? - Composted - Threw it in the trash | G6: 4 | H6: =G6*1.5 -> 6 | I6: No remaining food = 4 pts OR Every meal with composted wasted food = -.5 pts (from available 4 pts) OR Every meal with trashed wasted food = -1 pt (from available 4 pts) | K6: =J6*1.5 -> 0 | L6: The average American wastes 290lbs of food/year – composting is a great option for food scraps, but isn’t a solution to wasted food. Most of the greenhouse gas emissions in the life cycle of our food is from food production, not end-of-life management. Be conscious of how you store food, the size of portions you take, and how you save left-overs to reduce wasted food. https://www.pca.state.mn.us/simple-ways-cut-food-waste
A7: 3 | B7: Helpful Option | C7: Action Throughout the Week | D7: 01 - Food | E7: Food and Drink | F7: Were the majority of your beverages (coffee, water, soda, etc.) today served in: - a reusable container - a single-use container (compostable, recyclable, styrofoam, etc.) | G7: 4 | H7: =G7 -> 4 | I7: Reusable = 4 pts OR Single-use (compostable, non-compostable, styrofoam) cup = 0 pts | K7: =J7 -> 0 | L7: It is estimated that around 4 billion Starbucks disposable cups are thrown away annually in the US alone. Many coffee shops offer a discount for bringing your own mug. It is easy to bring your own mug to meetings and other events to avoid using disposable options when reusable mugs aren't made available. Learn More: More than Cups: Considering Sustainability in the Coffee Shop Industry - Daily Coffee News
A8: 4 | B8: Helpful Option | C8: Action Throughout the Week | D8: 01 - Food | E8: Food and Drink | F8: Did you order food today as take-out, delivery, or fast food? | G8: 4 | H8: =G8 -> 4 | I8: No ordered food = 4 pts OR Ordered food (delivered, take-out, fast food) = 0 pts | K8: =J8 -> 0 | L8: Did you know you can bring your own Tupperware to take leftovers home when you can’t finish your meal out? Keep one in your car and/or bag so you don't need to create demand for the single-use options.
A9: 5 | B9: Best Option | C9: Action Throughout the Week | D9: 02 - Shelter & Energy | E9: Unplug Electronics | F9: Did you unplug the electronics and appliances you own that draw the most power (i.e. computer and phone chargers, coffee maker, desktop, etc.) today? | G9: 4 | H9: =G9*2 -> 8 | I9: Unplugged electronics = 4 pts OR Didn't unplug electronics = 0 pts | K9: =J9*2 -> 0 | L9: Back in the day there was a difference between on and off. Now, it’s more complicated and roughly 50 devices and appliances in the typical American household are always drawing power, even when they appear to be off. Turn off power strips, and unplug when not in use! https://cleantechnica.com/2015/02/18/room-room-guide-ousting-energy-vampires-lurking-home/
A10: 6 | B10: Good Option | C10: Action Throughout the Week | D10: 02 - Shelter & Energy | E10: Shut Off Computer | F10: Did you shut off your computer/monitor at the end of the day? - Yes - No - Unsure Did you put your computer to sleep (lock, turn off monitors) when you were away throughout today? - Yes - No - Some of the time | G10: 4 | H10: =G10*1.5 -> 6 | I10: Shut off computer/monitor = 2 pts OR Unsure OR Didn't shut off computer/monitor = 0 pts AND Put computer to sleep when away = 2 pts OR Put computer to sleep some of the time = 1 pt OR Didn't put computer to sleep = 0 pts | K10: =J10*1.5 -> 0
A11: 7 | B11: Helpful Option | C11: Action Throughout the Week | D11: 02 - Shelter & Energy | E11: Blinds | F11: Did you shut your blinds during the day (summer) / at night (winter)? | G11: 4 | H11: =G11 -> 4 | I11: Blinds shut = 4 pts OR Blinds not shut = 0 pts | K11: =J11 -> 0 | L11: We all love natural light, especially if it allows to turn off indoor lighting, but when the sun is at its peak it's best to shut the blinds to keep the temperature down. Similarly in the winter, closing the blinds at night helps keeping the heat inside and unnecessarily cooling through exposed windows. Typical households and workplaces abuse thermostats, keeping it unnecessarily cool in the summer and overheated in the winter. Dress for the season to minimize your use!
A12: 8 | B12: Best Option | C12: Action Throughout the Week | D12: 03 - Mobility | E12: General Travel | F12: Did you use a personal vehicle today? What type of personal vehicle was used? - Gas-powered vehicle - Hybrid vehicle - Plug-in hybrid vehicle - All electric vehicle Did you carpool? | G12: 4 | H12: =G12*2 -> 8 | I12: No personal vehicle = 4 pts OR All electric vehicle = 3 pts OR Hybrid OR Plug-in hybrid vehicle = 2 pts Gas-powered vehicle = 0 pts AND Carpool = +1 pt No carpool = 0 pts | K12: =J12*2 -> 0 | L12: Nearly half of all air pollution in our state comes from vehicles. So one of the greatest contributions we can all make to improving air quality is to use alternatives to driving a car, especially as a sole occupant. Plus, did you know the MPCA is named a Bicycle Friendly Business? https://www.pca.state.mn.us/bus-bike-and-walk
A13: 9 | B13: Helpful Option | C13: Action Throughout the Week | D13: 03 - Mobility | E13: Planning | F13: Did you start your day today by planning your route and activities to minimize unnecessary or extra travel? - Yes - Yes - I made a plan but I had to deviate from the plan today - No | G13: 4 | H13: =G13 -> 4 | I13: Yes, planned = 4 pts OR Yes, but deviated = 2 pts OR No plan = 0 pts | K13: =J13 -> 0
A14: 10 | B14: Good Option | C14: Action Throughout the Week | D14: 03 - Mobility | E14: Work Travel | F14: Did you have to travel for work today? Did you use an alternative, more sustainable form of transportation for your work travel? - All electric vehicle - Public transportation - Bike/scooter/walk - Carpool | G14: 4 | H14: =G14*1.5 -> 6 | I14: No work travel OR Bike/scooter/walk = 4 pts OR Public transportation = 3 pts OR All electric vehicle OR Carpool = 2pts OR Travel without sustainable transport = 0 pts | K14: =J14*1.5 -> 0 | L14: If you're unsure how to navigate alternative transportation, never fear! The MPCA Sustainable Transit Team can provide tips, advice, and input on your best options. https://lorax.pca.state.mn.us/sustainable-transit-team
A15: 11 | B15: Helpful Option | C15: Action Throughout the Week | D15: 03 - Mobility | E15: Stairs | F15: Did you use the stairs instead of taking the elevator throughout the day today? - Yes - all the time - Yes - some of the time - No - always used the elevator | G15: 4 | H15: =G15 -> 4 | I15: All the time = 4 pts OR Some of the time = 2 pts OR Always used elevator = 0 pts | K15: =J15 -> 0 | L15: Taking the stairs has an environmental benefit because it lessens the energy consumption of our building, but it also offers important health benefits by lowering bad cholesterol levels, relieving stress, increase muscle strength, and improving joint health. http://www.startribune.com/want-a-cheap-way-to-get-healthier-and-develop-a-fabulous-butt-take-the-stairs/506050542/
A16: 12 | B16: Best Option | C16: Action Throughout the Week | D16: 04 - Goods/Services | E16: Single-Use Plastic | F16: Did you use single-use food and beverage items (including bottles/cans, containers, service ware, and utensils) today? | G16: 4 | H16: =G16*2 -> 8 | I16: Used single-use items = 0 pts OR Didn't use single-use items = 4 pts | K16: =J16*2 -> 0 | L16: Recyclable and compostable plastics are still single-use and have an environmental footprint – avoid use of these options by bringing your own plates/utensils/napkins to the MPCA cafeteria. https://lorax.pca.state.mn.us/news/reduce-waste-and-take-your-own-dishes-cafeteria
A17: 13 | B17: Best Option | C17: Action Throughout the Week | D17: 04 - Goods/Services | E17: Sustainable Cleaning | F17: Did you use non-toxic cleaning solutions and a reusable cleaning cloth/device (instead of paper towels, chemicals, etc.) when you cleaned today? | G17: 4 | H17: =G17*2 -> 8 | I17: Sustainable cleaning = 4 pts OR No sustainable cleaning = 0 pts | K17: =J17*2 -> 0 | L17: If you didn't clean every day, you may want to change some personal habits - kidding! MPCA have invested a lot of effort reaching out to community groups about the dangers of harsh, chemical-heavy cleaners. The best part is you can make them yourself and reduce the number of different cleaners needed for all of your household surfaces. Check out the Hennepin County video on FB for a tutorial: https://www.facebook.com/hennepin/videos/vb.211281525566478/2448986885120718/?type=2&theater
A18: 14 | B18: Good Option | C18: Action Throughout the Week | D18: 04 - Goods/Services | E18: Online Shopping | F18: Did you buy anything online today? | G18: 4 | H18: =G18*1.5 -> 6 | I18: Shopped online = 0 pts OR No online shopping = 4 pts | K18: =J18*1.5 -> 0
A19: 15 | B19: Good Option | C19: Action Throughout the Week | D19: 04 - Goods/Services | E19: Reusable Bags | F19: Did you shop for consumer goods (groceries, clothes, etc.) today? What bags did you use? - No bags - Reusable bags - Plastic/paper bags from the retailer | G19: 4 | H19: =G19*1.5 -> 6 | I19: No shopping = 4 pts OR No bags OR Reusable bags = 4 pts OR Plastic/paper bags = 0 pts | K19: =J19*1.5 -> 0 | L19: Have you checked out the bag tree set up by the lower-level exit to the parking lot? If you forget a bag and need to borrow one, take it and bring it back the next day. The Sustainability Team will clean and repair any that need fixing. https://lorax.pca.state.mn.us/news/tote-ally-sustainable-bag-share-station
A20: 16 | B20: Helpful Option | C20: Action Throughout the Week | D20: 04 - Goods/Services | E20: Paper Towels | F20: When drying your hands in the restroom today, did you: - Use multiple single-use paper towels - Use single-use paper towels, but ONLY one each time - Use a reusable cloth towel - Ues an electric hand dryer - Air dry/Shake it off | G20: 4 | H20: =G20 -> 4 | I20: Multiple single-use = 0 pts OR One single-use = 1 pt OR Electric hand dryer = 2 pts OR Reusable cloth towel = 3 pts OR Air dry/Shake it off = 4 pts | K20: =J20 -> 0 | L20: At home, use reusable cloths and/or rags. At work you can air-dry, or if you need help getting down to just one paper towel to start, check out this TED talk for instructions. https://www.ted.com/talks/joe_smith_how_to_use_a_paper_towel?language=en
A21: 17 | B21: Helpful Option | C21: Action Throughout the Week | D21: 04 - Goods/Services | E21: Printing | F21: Did you email documents, share or present a computer screen, and/or share via Skype/WebEex to avoid printing today? - Yes - all of the time - Yes - some of the time - No - always provided printed versions | G21: 4 | H21: =G21 -> 4 | I21: All the time = 4 pts OR Some of the time = 2 pts OR Always provided printed = 0 pts | K21: =J21 -> 0 | L21: Emailing agendas and meeting notes is just as helpful, if not more, than using paper with printed versions. Speaking of more sustainable meetings - are you using the green meeting checklist every time you plan or attend a meeting? https://lorax.pca.state.mn.us/green-meetings
A22: 18 | B22: Good Option | C22: Action Throughout the Week | D22: 05 - Water | E22: Washing Dishes | F22: When washing dishes today, did you primarily wash using: - A dishwasher - Pre-rinse and then a dishwasher - Hand washing in hot water - Hand washing in cold water | G22: 4 | H22: =G22*1.5 -> 6 | I22: Dishwasher = 4 pts OR Pre-rinse and dishwasher = 0 pts OR Hand wash in hot = 1 pts OR Hand wash in cold = 2 pts | K22: =J22*1.5 -> 0 | L22: Studies show that washing a load of dishes by hand can use up to 27 gallons of water and 2.5 kWh of energy to heat the water versus just 4 gallons of water and 1 kWH of energy when using an energy-efficient dishwasher (with a full load!) Learn More: Which is Better for the Enviornment: Washing Dishes By Hand Or The Dishwasher? - Huffpost
A23: 19 | B23: Best Option | C23: Action Throughout the Week | D23: 05 - Water | E23: Bathing | F23: Did you bathe today? - Yes - shower - Yes - bath - No (we aren't judging!) Did you shower for five minutes or less? Did you turn off the water while lathering and shaving? | G23: 4 | H23: =G23*2 -> 8 | I23: No Bathing = 4 pts OR Bath = 1 pt OR Shower = 2 pts AND Less than five min = +.5 pt OR Water off while lathering/shaving = +.5 pt | K23: =J23*2 -> 0
A24: 20 | B24: Helpful Option | C24: Action Throughout the Week | D24: 05 - Water | E24: Brushing Teeth | F24: Did you turn off the water while you brushed your teeth? | G24: 4 | H24: =G24 -> 4 | I24: Water off = 4 pts OR Water on = 0 pts | K24: =J24 -> 0
A25: 21 | B25: Good Option | C25: Action Throughout the Week | D25: 05 - Water | E25: Water Quality | F25: Did you maintain icy sidewalks or driveways today? What management style did you use primarily? - Plow, shovel, scrape - Reusable abrasives for traction (e.g. sand) - Deicers - Deicers, adhering to rules for the correct amount, distribution, and temperature | G25: 4 | H25: =G25*1.5 -> 6 | I25: No maintenance OR Plow, shovel, scrape = 4 pts OR Reusable abrasives = 3 pts OR Deicers, adhering to rules = 2 pts OR Deicers = 0 pts | K25: =J25*1.5 -> 0 | L25: Smart salting is important for local water quality. Use the Smart Salting Assessment tool to determine best practices and reduce salt use. Learn More: Smart Salting Assessment tool - MPCA
G26: =SUM(G5:G25) -> 84 | H26: =SUM(H5:H25) -> 122 | J26: =SUM(J5:J25) -> 0 | K26: =SUM(K5:K25) -> 0
G27: Available (unweighted) | H27: Available (weighted) | J27: Earned Total (unweighted) | K27: Earned Total (weighted)

Sheet Daily Scoring - Day 3
D1: DAILY SCORING - DAY 3
A2: Participant: | C2: ='Final Scoring'!C2 -> 0
A3: Sustainability Team Member: | C3: ='Final Scoring'!C3 -> 0
A4: # | B4: Environmental Benefit | C4: In person task? Action throughout the week? | D4: Category | E4: Subcategory | F4: Behavior/Action | G4: Points Available | H4: Weighted Available Points | I4: Point Scoring | J4: Points Earned | K4: Point Total (weighted by "Best," "Good," or "Helpful" action) | L4: Sustainability Tip
A5: 1 | B5: Best Option | C5: Action Throughout the Week | D5: 01 - Food | E5: Meatless | F5: Did you eat meat (red meat, white meat, fish/seafood) today? Did you eat primarily: - Red meat (beef, pork, lamb, etc.) - White meat (chicken) - Fish/seafood Was it locally sourced and organic? - Yes - No - Unsure | G5: 4 | H5: =G5*2 -> 8 | I5: No meat = 4 pts OR Red meat = 0 pts OR White meant OR Fish/seafood = 1 pt AND Local/Organic = +1 pt No OR Unsure = 0 pts | K5: =J5*2 -> 0 | L5: Already a vegetarian? Reduce your impact further by reducing the amount of animal products you consume (cheese, eggs, etc.), and choose organic, local options. It’s better for your health and great support for the MN economy! https://www.nytimes.com/interactive/2019/04/30/dining/climate-change-food-eating-habits.html
A6: 2 | B6: Good Option | C6: Action Throughout the Week | D6: 01 - Food | E6: Wasted Food | F6: Did you have food remaining that you didn’t save to eat later at any meals today? How many meals had wasted food? - Breakfast - Lunch - Dinner - Snacks only Did you compost or trash the wasted food? - Composted - Threw it in the trash | G6: 4 | H6: =G6*1.5 -> 6 | I6: No remaining food = 4 pts OR Every meal with composted wasted food = -.5 pts (from available 4 pts) OR Every meal with trashed wasted food = -1 pt (from available 4 pts) | K6: =J6*1.5 -> 0 | L6: The average American wastes 290lbs of food/year – composting is a great option for food scraps, but isn’t a solution to wasted food. Most of the greenhouse gas emissions in the life cycle of our food is from food production, not end-of-life management. Be conscious of how you store food, the size of portions you take, and how you save left-overs to reduce wasted food. https://www.pca.state.mn.us/simple-ways-cut-food-waste
A7: 3 | B7: Helpful Option | C7: Action Throughout the Week | D7: 01 - Food | E7: Food and Drink | F7: Were the majority of your beverages (coffee, water, soda, etc.) today served in: - a reusable container - a single-use container (compostable, recyclable, styrofoam, etc.) | G7: 4 | H7: =G7 -> 4 | I7: Reusable = 4 pts OR Single-use (compostable, non-compostable, styrofoam) cup = 0 pts | K7: =J7 -> 0 | L7: It is estimated that around 4 billion Starbucks disposable cups are thrown away annually in the US alone. Many coffee shops offer a discount for bringing your own mug. It is easy to bring your own mug to meetings and other events to avoid using disposable options when reusable mugs aren't made available. Learn More: More than Cups: Considering Sustainability in the Coffee Shop Industry - Daily Coffee News
A8: 4 | B8: Helpful Option | C8: Action Throughout the Week | D8: 01 - Food | E8: Food and Drink | F8: Did you order food today as take-out, delivery, or fast food? | G8: 4 | H8: =G8 -> 4 | I8: No ordered food = 4 pts OR Ordered food (delivered, take-out, fast food) = 0 pts | K8: =J8 -> 0 | L8: Did you know you can bring your own Tupperware to take leftovers home when you can’t finish your meal out? Keep one in your car and/or bag so you don't need to create demand for the single-use options.
A9: 5 | B9: Best Option | C9: Action Throughout the Week | D9: 02 - Shelter & Energy | E9: Unplug Electronics | F9: Did you unplug the electronics and appliances you own that draw the most power (i.e. computer and phone chargers, coffee maker, desktop, etc.) today? | G9: 4 | H9: =G9*2 -> 8 | I9: Unplugged electronics = 4 pts OR Didn't unplug electronics = 0 pts | K9: =J9*2 -> 0 | L9: Back in the day there was a difference between on and off. Now, it’s more complicated and roughly 50 devices and appliances in the typical American household are always drawing power, even when they appear to be off. Turn off power strips, and unplug when not in use! https://cleantechnica.com/2015/02/18/room-room-guide-ousting-energy-vampires-lurking-home/
A10: 6 | B10: Good Option | C10: Action Throughout the Week | D10: 02 - Shelter & Energy | E10: Shut Off Computer | F10: Did you shut off your computer/monitor at the end of the day? - Yes - No - Unsure Did you put your computer to sleep (lock, turn off monitors) when you were away throughout today? - Yes - No - Some of the time | G10: 4 | H10: =G10*1.5 -> 6 | I10: Shut off computer/monitor = 2 pts OR Unsure OR Didn't shut off computer/monitor = 0 pts AND Put computer to sleep when away = 2 pts OR Put computer to sleep some of the time = 1 pt OR Didn't put computer to sleep = 0 pts | K10: =J10*1.5 -> 0
A11: 7 | B11: Helpful Option | C11: Action Throughout the Week | D11: 02 - Shelter & Energy | E11: Blinds | F11: Did you shut your blinds during the day (summer) / at night (winter)? | G11: 4 | H11: =G11 -> 4 | I11: Blinds shut = 4 pts OR Blinds not shut = 0 pts | K11: =J11 -> 0 | L11: We all love natural light, especially if it allows to turn off indoor lighting, but when the sun is at its peak it's best to shut the blinds to keep the temperature down. Similarly in the winter, closing the blinds at night helps keeping the heat inside and unnecessarily cooling through exposed windows. Typical households and workplaces abuse thermostats, keeping it unnecessarily cool in the summer and overheated in the winter. Dress for the season to minimize your use!
A12: 8 | B12: Best Option | C12: Action Throughout the Week | D12: 03 - Mobility | E12: General Travel | F12: Did you use a personal vehicle today? What type of personal vehicle was used? - Gas-powered vehicle - Hybrid vehicle - Plug-in hybrid vehicle - All electric vehicle Did you carpool? | G12: 4 | H12: =G12*2 -> 8 | I12: No personal vehicle = 4 pts OR All electric vehicle = 3 pts OR Hybrid OR Plug-in hybrid vehicle = 2 pts Gas-powered vehicle = 0 pts AND Carpool = +1 pt No carpool = 0 pts | K12: =J12*2 -> 0 | L12: Nearly half of all air pollution in our state comes from vehicles. So one of the greatest contributions we can all make to improving air quality is to use alternatives to driving a car, especially as a sole occupant. Plus, did you know the MPCA is named a Bicycle Friendly Business? https://www.pca.state.mn.us/bus-bike-and-walk
A13: 9 | B13: Helpful Option | C13: Action Throughout the Week | D13: 03 - Mobility | E13: Planning | F13: Did you start your day today by planning your route and activities to minimize unnecessary or extra travel? - Yes - Yes - I made a plan but I had to deviate from the plan today - No | G13: 4 | H13: =G13 -> 4 | I13: Yes, planned = 4 pts OR Yes, but deviated = 2 pts OR No plan = 0 pts | K13: =J13 -> 0
A14: 10 | B14: Good Option | C14: Action Throughout the Week | D14: 03 - Mobility | E14: Work Travel | F14: Did you have to travel for work today? Did you use an alternative, more sustainable form of transportation for your work travel? - All electric vehicle - Public transportation - Bike/scooter/walk - Carpool | G14: 4 | H14: =G14*1.5 -> 6 | I14: No work travel OR Bike/scooter/walk = 4 pts OR Public transportation = 3 pts OR All electric vehicle OR Carpool = 2pts OR Travel without sustainable transport = 0 pts | K14: =J14*1.5 -> 0 | L14: If you're unsure how to navigate alternative transportation, never fear! The MPCA Sustainable Transit Team can provide tips, advice, and input on your best options. https://lorax.pca.state.mn.us/sustainable-transit-team
A15: 11 | B15: Helpful Option | C15: Action Throughout the Week | D15: 03 - Mobility | E15: Stairs | F15: Did you use the stairs instead of taking the elevator throughout the day today? - Yes - all the time - Yes - some of the time - No - always used the elevator | G15: 4 | H15: =G15 -> 4 | I15: All the time = 4 pts OR Some of the time = 2 pts OR Always used elevator = 0 pts | K15: =J15 -> 0 | L15: Taking the stairs has an environmental benefit because it lessens the energy consumption of our building, but it also offers important health benefits by lowering bad cholesterol levels, relieving stress, increase muscle strength, and improving joint health. http://www.startribune.com/want-a-cheap-way-to-get-healthier-and-develop-a-fabulous-butt-take-the-stairs/506050542/
A16: 12 | B16: Best Option | C16: Action Throughout the Week | D16: 04 - Goods/Services | E16: Single-Use Plastic | F16: Did you use single-use food and beverage items (including bottles/cans, containers, service ware, and utensils) today? | G16: 4 | H16: =G16*2 -> 8 | I16: Used single-use items = 0 pts OR Didn't use single-use items = 4 pts | K16: =J16*2 -> 0 | L16: Recyclable and compostable plastics are still single-use and have an environmental footprint – avoid use of these options by bringing your own plates/utensils/napkins to the MPCA cafeteria. https://lorax.pca.state.mn.us/news/reduce-waste-and-take-your-own-dishes-cafeteria
A17: 13 | B17: Best Option | C17: Action Throughout the Week | D17: 04 - Goods/Services | E17: Sustainable Cleaning | F17: Did you use non-toxic cleaning solutions and a reusable cleaning cloth/device (instead of paper towels, chemicals, etc.) when you cleaned today? | G17: 4 | H17: =G17*2 -> 8 | I17: Sustainable cleaning = 4 pts OR No sustainable cleaning = 0 pts | K17: =J17*2 -> 0 | L17: If you didn't clean every day, you may want to change some personal habits - kidding! MPCA have invested a lot of effort reaching out to community groups about the dangers of harsh, chemical-heavy cleaners. The best part is you can make them yourself and reduce the number of different cleaners needed for all of your household surfaces. Check out the Hennepin County video on FB for a tutorial: https://www.facebook.com/hennepin/videos/vb.211281525566478/2448986885120718/?type=2&theater
A18: 14 | B18: Good Option | C18: Action Throughout the Week | D18: 04 - Goods/Services | E18: Online Shopping | F18: Did you buy anything online today? | G18: 4 | H18: =G18*1.5 -> 6 | I18: Shopped online = 0 pts OR No online shopping = 4 pts | K18: =J18*1.5 -> 0
A19: 15 | B19: Good Option | C19: Action Throughout the Week | D19: 04 - Goods/Services | E19: Reusable Bags | F19: Did you shop for consumer goods (groceries, clothes, etc.) today? What bags did you use? - No bags - Reusable bags - Plastic/paper bags from the retailer | G19: 4 | H19: =G19*1.5 -> 6 | I19: No shopping = 4 pts OR No bags OR Reusable bags = 4 pts OR Plastic/paper bags = 0 pts | K19: =J19*1.5 -> 0 | L19: Have you checked out the bag tree set up by the lower-level exit to the parking lot? If you forget a bag and need to borrow one, take it and bring it back the next day. The Sustainability Team will clean and repair any that need fixing. https://lorax.pca.state.mn.us/news/tote-ally-sustainable-bag-share-station
A20: 16 | B20: Helpful Option | C20: Action Throughout the Week | D20: 04 - Goods/Services | E20: Paper Towels | F20: When drying your hands in the restroom today, did you: - Use multiple single-use paper towels - Use single-use paper towels, but ONLY one each time - Use a reusable cloth towel - Ues an electric hand dryer - Air dry/Shake it off | G20: 4 | H20: =G20 -> 4 | I20: Multiple single-use = 0 pts OR One single-use = 1 pt OR Electric hand dryer = 2 pts OR Reusable cloth towel = 3 pts OR Air dry/Shake it off = 4 pts | K20: =J20 -> 0 | L20: At home, use reusable cloths and/or rags. At work you can air-dry, or if you need help getting down to just one paper towel to start, check out this TED talk for instructions. https://www.ted.com/talks/joe_smith_how_to_use_a_paper_towel?language=en
A21: 17 | B21: Helpful Option | C21: Action Throughout the Week | D21: 04 - Goods/Services | E21: Printing | F21: Did you email documents, share or present a computer screen, and/or share via Skype/WebEex to avoid printing today? - Yes - all of the time - Yes - some of the time - No - always provided printed versions | G21: 4 | H21: =G21 -> 4 | I21: All the time = 4 pts OR Some of the time = 2 pts OR Always provided printed = 0 pts | K21: =J21 -> 0 | L21: Emailing agendas and meeting notes is just as helpful, if not more, than using paper with printed versions. Speaking of more sustainable meetings - are you using the green meeting checklist every time you plan or attend a meeting? https://lorax.pca.state.mn.us/green-meetings
A22: 18 | B22: Good Option | C22: Action Throughout the Week | D22: 05 - Water | E22: Washing Dishes | F22: When washing dishes today, did you primarily wash using: - A dishwasher - Pre-rinse and then a dishwasher - Hand washing in hot water - Hand washing in cold water | G22: 4 | H22: =G22*1.5 -> 6 | I22: Dishwasher = 4 pts OR Pre-rinse and dishwasher = 0 pts OR Hand wash in hot = 1 pts OR Hand wash in cold = 2 pts | K22: =J22*1.5 -> 0 | L22: Studies show that washing a load of dishes by hand can use up to 27 gallons of water and 2.5 kWh of energy to heat the water versus just 4 gallons of water and 1 kWH of energy when using an energy-efficient dishwasher (with a full load!) Learn More: Which is Better for the Enviornment: Washing Dishes By Hand Or The Dishwasher? - Huffpost
A23: 19 | B23: Best Option | C23: Action Throughout the Week | D23: 05 - Water | E23: Bathing | F23: Did you bathe today? - Yes - shower - Yes - bath - No (we aren't judging!) Did you shower for five minutes or less? Did you turn off the water while lathering and shaving? | G23: 4 | H23: =G23*2 -> 8 | I23: No Bathing = 4 pts OR Bath = 1 pt OR Shower = 2 pts AND Less than five min = +.5 pt OR Water off while lathering/shaving = +.5 pt | K23: =J23*2 -> 0
A24: 20 | B24: Helpful Option | C24: Action Throughout the Week | D24: 05 - Water | E24: Brushing Teeth | F24: Did you turn off the water while you brushed your teeth? | G24: 4 | H24: =G24 -> 4 | I24: Water off = 4 pts OR Water on = 0 pts | K24: =J24 -> 0
A25: 21 | B25: Good Option | C25: Action Throughout the Week | D25: 05 - Water | E25: Water Quality | F25: Did you maintain icy sidewalks or driveways today? What management style did you use primarily? - Plow, shovel, scrape - Reusable abrasives for traction (e.g. sand) - Deicers - Deicers, adhering to rules for the correct amount, distribution, and temperature | G25: 4 | H25: =G25*1.5 -> 6 | I25: No maintenance OR Plow, shovel, scrape = 4 pts OR Reusable abrasives = 3 pts OR Deicers, adhering to rules = 2 pts OR Deicers = 0 pts | K25: =J25*1.5 -> 0 | L25: Smart salting is important for local water quality. Use the Smart Salting Assessment tool to determine best practices and reduce salt use. Learn More: Smart Salting Assessment tool - MPCA
G26: =SUM(G5:G25) -> 84 | H26: =SUM(H5:H25) -> 122 | J26: =SUM(J5:J25) -> 0 | K26: =SUM(K5:K25) -> 0
G27: Available (unweighted) | H27: Available (weighted) | J27: Earned Total (unweighted) | K27: Earned Total (weighted)

Sheet Daily Scoring - Day 4
D1: DAILY SCORING - DAY 4
A2: Participant: | C2: ='Final Scoring'!C2 -> 0
A3: Sustainability Team Member: | C3: ='Final Scoring'!C3 -> 0
A4: # | B4: Environmental Benefit | C4: In person task? Action throughout the week? | D4: Category | E4: Subcategory | F4: Behavior/Action | G4: Points Available | H4: Weighted Available Points | I4: Point Scoring | J4: Points Earned | K4: Point Total (weighted by "Best," "Good," or "Helpful" action) | L4: Sustainability Tip
A5: 1 | B5: Best Option | C5: Action Throughout the Week | D5: 01 - Food | E5: Meatless | F5: Did you eat meat (red meat, white meat, fish/seafood) today? Did you eat primarily: - Red meat (beef, pork, lamb, etc.) - White meat (chicken) - Fish/seafood Was it locally sourced and organic? - Yes - No - Unsure | G5: 4 | H5: =G5*2 -> 8 | I5: No meat = 4 pts OR Red meat = 0 pts OR White meant OR Fish/seafood = 1 pt AND Local/Organic = +1 pt No OR Unsure = 0 pts | K5: =J5*2 -> 0 | L5: Already a vegetarian? Reduce your impact further by reducing the amount of animal products you consume (cheese, eggs, etc.), and choose organic, local options. It’s better for your health and great support for the MN economy! https://www.nytimes.com/interactive/2019/04/30/dining/climate-change-food-eating-habits.html
